def bad_fun(n):
    """
    This code demonstrates exception inside a function
    """
    try:
        return 1/n
    except ZeroDivisionError as err:
        print(err, "from inside.")
        raise  # 'raise; can be with or with ot parameter
        raise (NameError, TypeError)

    """
    This code demonstrates exception outside a function
    """


try:
    bad_fun(0)
except ArithmeticError :
    print("Arithmetic Error from Outside")
except NameError as #  Copyright (c) 2024. Lorem ipsum dolor sit amet, consectetur adipiscing elit.
#  Date & Time 14/04/2024, 21:56.
#  @author Mesfin Haftu

#  Date & Time 14/04/2024, 21:55.
#  @author Mesfin Haftu

#  Date & Time 14/04/2024, 21:54.
#  @author Mesfin Haftu

#  Date & Time (\d+)", 1, "-")14/04/2024, 21:53.
#  @author Mesfin Haftu

#  Morbi non lorem porttitor neque feugiat blandit. Ut vitae ipsum eget quam lacinia accumsan.
#  Etiam sed turpis ac ipsum condimentum fringilla. Maecenas magna.
#  Proin dapibus sapien vel ante. Aliquam erat volutpat. Pellentesque sagittis ligula eget metus.
#  Vestibulum commodo. Ut rhoncus gravida arcu.

err:
    print(err)
except TypeError as err:
    print(err)





